#异常，断言，日志和调试

**违例差错控制**

**##异常处理机制**
异常处理是对可能出现的异常进行处理，以防止程序遇到异常时被卡死，处于一直等待，或死循环。

异常有两个过程，一个是抛出异常；一个是捕捉异常。

**###抛出异常**

抛出异常有三种形式，一是throw,一个throws，还有一种系统自动抛异常。下面它们之间的异同。

**系统自动抛异常**

当程序语句出现一些逻辑错误、主义错误或类型转换错误时，系统会自动抛出异常。如：
```
public static void main(String[] args) {          
      int a = 5, b =0;          
      System.out.println(5/b);          
      //function();  }  
系统会自动抛出ArithmeticException异常：

Exception in thread "main" java.lang.ArithmeticException: / by zero
at test.ExceptionTest.main(ExceptionTest.java:62)
```

  再如
```
public static void main(String[] args) {  
        String s = "abc";  
        System.out.println(Double.parseDouble(s));  
        //function();  
}  


系统会自动抛出NumberFormatException异常：

Exception in thread "main" java.lang.NumberFormatException: For input string: "abc"
at sun.misc.FloatingDecimal.readJavaFormatString(FloatingDecimal.java:1224)
at java.lang.Double.parseDouble(Double.java:510)
at test.ExceptionTest.main(ExceptionTest.java:62)
```

**throw**

throw是语句抛出一个异常。

语法：throw (异常对象);
      如：  throw e;
      
一般会用于程序出现某种逻辑时程序员主动抛出某种特定类型的异常。如：

```
public static void main(String[] args) {  
        String s = "abc";  
        if(s.equals("abc")) {  
            throw new NumberFormatException();  
        } else {  
            System.out.println(s);  
        }  
        //function();  
}  

会抛出异常：
Exception in thread "main" java.lang.NumberFormatException
at test.ExceptionTest.main(ExceptionTest.java:67)
```

**throws**

throws是方法可能抛出异常的声明。(用在声明方法时，表示该方法可能要抛出异常)

语法：[(修饰符)](返回值类型)(方法名)([参数列表])[throws(异常类)]{......}

      如：      public void function() throws Exception{......}
      
当某个方法可能会抛出某种异常时用于throws 声明可能抛出的异常，然后交给上层调用它的方法程序处理。如：

```
public static void function() throws NumberFormatException{  
        String s = "abc";  
        System.out.println(Double.parseDouble(s));  
    }  
      
    public static void main(String[] args) {  
        try {  
            function();  
        } catch (NumberFormatException e) {  
            System.err.println("非数据类型不能转换。");  
            //e.printStackTrace();  
        }  
}  
```
非数据类型不能转换。

**throw与throws的比较**
1、throws出现在方法函数头；而throw出现在函数体。
2、throws表示出现异常的一种可能性，并不一定会发生这些异常；throw则是抛出了异常，执行throw则一定抛出了某种异常对象。
3、两者都是消极处理异常的方式（这里的消极并不是说这种方式不好），只是抛出或者可能抛出异常，但是不会由函数去处理异常，真正的处理异常由函数的上层调用处理。


好的编程习惯：
1.在写程序时，对可能会出现异常的部分通常要用try{...}catch{...}去捕捉它并对它进行处理；
2.用try{...}catch{...}捕捉了异常之后一定要对在catch{...}中对其进行处理，那怕是最简单的一句输出语句，或栈输入e.printStackTrace();
3.如果是捕捉IO输入输出流中的异常，一定要在try{...}catch{...}后加finally{...}把输入输出流关闭；
4.如果在函数体内用throw抛出了某种异常，最好要在函数名中加throws抛异常声明，然后交给调用它的上层函数进行处理。


**##捕捉异常**

```
try{  
　……  
}catch(Exception e){  
　……  
}finally{  
　……  
}  
```
try{……}中放置可能会发生异常的的语句块，如可能出现异常的函数，也可以是一般的程序语句；catch(){……}用于抓住异常，(Exception e)中Exception是异常的类型，必须是Exception(Exception是所有异常类的父类)的子类。{}定义当出现异常时的处理方法。finally{……}表示不管异常是否发生，都得进行finally{}中的处理。

在捕捉异常的try{...}语句块中，如果出现了异常，则该语句(出现异常的语句)后的程序语句都不执行，而是跳到catch{...}语句块中执行异常的处理。如：
```
public static void function1() throws NumberFormatException{  
        System.out.println(Double.parseDouble("abc"));  
        System.out.println("第二条语句。");  
          
    }  
  
    public static void main(String[] args) {  
        try {  
            function1();  
        } catch (Exception e) {  
            System.err.println(e.getMessage());  
            //e.printStackTrace();  
        }  
}  
```
结果如下，只输出了一条错误提示语：

For input string: "abc"

System.out.println("第二条语句。");未执行。


如果一个函数没有用throws进行抛异常，在调用该函数的方法也同样可以捕捉异常。如
 ```
public static void function() {  
        String s = "abc";  
        System.out.println(Double.parseDouble(s));  
    }  
      
    public static void main(String[] args) {  
        try {  
            function();  
        } catch (Exception e) {  
            System.err.println("非数据类型不能转换。");  
            //e.printStackTrace();  
        }  
}  
```

非数据类型不能转换。

说明：某个函数或某段程序块不管会不会，有没可能抛出异常，都可以加try{...}catch{...}去捕捉它。


**自定义异常**

用户可以自定义异常，新建一个异常类，让其继承Exception类或Exception的某个子类。然后用throw抛出自己定义的异常类对象。如：

```
public static void function() throws ParenthesisMatchingException{  
        String s = "((a+b)";  
        ParenthesisMatchingException e = new ParenthesisMatchingException("括号匹配异常！");  
        if(s.charAt(0)=='(' && s.charAt(1)=='(') {  
            throw e;  
        }  
        System.out.println(s);  
    }  
      
    public static void main(String[] args) {  
        try {  
            function();  
        } catch (Exception e) {  
            System.out.println(e.getMessage());  
            //e.printStackTrace();  
        }  
}  
```
结果如下 ：
括号匹配异常！

**异常分类**

所有的异常都是由Throwable继承而来，但在下一层立即分解为两个分支：Error和Exception

Error类描述了java运行时系统的内部错误和资源耗尽错误

Exception又分解为两个分支：

1）RuntimeException

包含下面这几种情况：

*数组访问越界

*错误的类型转换

*访问空指针

2）IOException

*试图在文件尾部后面读取数据

*试图打开一个不存在的文件

*试图根据给定的字符串查找Class对象，而这个字符串表示的类根本不存在

**未检查异常**：派生于Error类或RuntimeException类的所有异常，其他的所有异常称为已检查异常

**一个方法必须声明所有可能抛出的已检查异常，而未检查要么不可控制（Error），要么就应该避免发生（RuntimeException）**

**##断言**

断言机制允许在测试期间向代码中插入一些检查语句，当代码发布时，这些插入的检测语句会被自动的移走

Java语言引入了关键字assert

assert 条件：

和

assert 条件： 表达式；

对条件进行检测，如果结果为false，则抛出一个AssertionError异常，在第二种形式中，表达式将被传入AssertionError的构造器，并转换成一个消息字符串

默认情况，断言被禁用，可以在运行程序时用-enableassertions或-ea来启用：
`java -ea Myapp`

用-disableassertions或-da禁用某个特定类和包的断言：
`java -ea:... -da:MyClass Myapp`

**##记录日志**

调用getLogger方法可以创建或检索记录器：
`private static final Logger myLogger=Logger.getLogger("com.mycompany.myapp"); `

有7个记录器级别：
*SEVERE
*WARNING
*INFO
*CONFIG
*FINE
*FINER
*FINEST

**##调试技巧**

只要在代码的任何位置插入Thread.dumpStack()；就可以获得堆栈跟踪

可以采用下面的方式，将堆栈跟踪捕获到一个字符串中：
```
ByteArrayOutputStream out=new ByteArrayOutputStream();
new Throwable().printStackTrace(out);
String description=out.toString();
```

可以用-verbose启动Java虚拟机，来观察类的加载过程：

Xlint选项告诉编译器对一些普通容易出现的代码问题进行检查
`java -Xlint:fallthrough `(检查swich语句中是否缺少break语句）
















